---
date: 2024-01-26 00:58:41.341745-07:00
description: "\u30A8\u30E9\u30FC\u51E6\u7406\u3068\u306F\u3001\u4E88\u671F\u305B\u306C\
  \u3053\u3068\u3092\u4E88\u6E2C\u3059\u308B\u3053\u3068\u3067\u3059\u3002\u30B3\u30FC\
  \u30C9\u3067\u554F\u984C\u304C\u767A\u751F\u3057\u305F\u969B\u306B\u3001\u305D\u308C\
  \u3092\u3069\u3046\u7BA1\u7406\u3059\u308B\u304B\u3068\u3044\u3046\u3053\u3068\u3067\
  \u3059\u3002\u30AF\u30E9\u30C3\u30B7\u30E5\u3092\u907F\u3051\u3001\u4E88\u671F\u305B\
  \u306C\u3053\u3068\u304C\u767A\u751F\u3057\u305F\u3068\u3057\u3066\u3082\u30E6\u30FC\
  \u30B6\u30FC\u306B\u30B9\u30E0\u30FC\u30BA\u306A\u7D4C\u9A13\u3092\u63D0\u4F9B\u3059\
  \u308B\u305F\u3081\u306B\u884C\u3044\u307E\u3059\u3002"
lastmod: '2024-03-13T22:44:41.770089-06:00'
model: gpt-4-1106-preview
summary: "\u30A8\u30E9\u30FC\u51E6\u7406\u3068\u306F\u3001\u4E88\u671F\u305B\u306C\
  \u3053\u3068\u3092\u4E88\u6E2C\u3059\u308B\u3053\u3068\u3067\u3059\u3002\u30B3\u30FC\
  \u30C9\u3067\u554F\u984C\u304C\u767A\u751F\u3057\u305F\u969B\u306B\u3001\u305D\u308C\
  \u3092\u3069\u3046\u7BA1\u7406\u3059\u308B\u304B\u3068\u3044\u3046\u3053\u3068\u3067\
  \u3059\u3002\u30AF\u30E9\u30C3\u30B7\u30E5\u3092\u907F\u3051\u3001\u4E88\u671F\u305B\
  \u306C\u3053\u3068\u304C\u767A\u751F\u3057\u305F\u3068\u3057\u3066\u3082\u30E6\u30FC\
  \u30B6\u30FC\u306B\u30B9\u30E0\u30FC\u30BA\u306A\u7D4C\u9A13\u3092\u63D0\u4F9B\u3059\
  \u308B\u305F\u3081\u306B\u884C\u3044\u307E\u3059\u3002."
title: "\u30A8\u30E9\u30FC\u51E6\u7406"
weight: 16
---

## 方法：
TypeScriptでは、エラー処理には多くの場合`try`、`catch`、`finally`ブロックが関わってきます。

```typescript
function riskyOperation() {
  throw new Error("何か問題が発生しました！");
}

function handleErrors() {
  try {
    riskyOperation();
  } catch (error) {
    console.error("エラーをキャッチしました：", error.message);
  } finally {
    console.log("これは常に実行されます、エラーがあろうとなかろうと。");
  }
}

handleErrors();
```

サンプル出力：

```
エラーをキャッチしました：何か問題が発生しました！
これは常に実行されます、エラーがあろうとなかろうと。
```

プロミスを用いた非同期の例：

```typescript
async function asyncRiskyOperation() {
  return new Promise((resolve, reject) => {
    // エラーをシミュレート
    reject("ひどく失敗しました");
  });
}

async function handleAsyncErrors() {
  try {
    await asyncRiskyOperation();
  } catch (error) {
    console.error("非同期エラーをキャッチしました：", error);
  }
}

handleAsyncErrors();
```

サンプル出力：

```
非同期エラーをキャッチしました：ひどく失敗しました
```

## 深堀り
エラー処理はプログラミングの礎石であり、始まりから存在しています。JavaScriptを基にしたTypeScriptでは、ECMAScript 2017でのasync/awaitの導入により、エラー処理がより堅牢になりました。それ以前は、非同期コード内のエラーを処理するためにコールバック関数やプロミスに頼ることが多かったです。

TypeScriptで`try/catch`の代わりに使用できる代替手段として、Reactのようなフレームワークによるエラーバウンダリがあります。サーバー側での処理には、Express.jsのようなプラットフォームでミドルウェアを使用してエラー管理を一元化することができます。

実装上では、TypeScriptには独自のエラー処理機構はなく、JavaScriptのものに依存しています。カスタムエラークラスは`Error`クラスを拡張して、より記述的なエラー情報を提供することができます。

## 関連項目
- [MDNのtry/catchについて](https://developer.mozilla.org/en-US/docs/Web/JavaScript/Reference/Statements/try...catch)
- [MDNのAsync/Awaitについて](https://developer.mozilla.org/en-US/docs/Learn/JavaScript/Asynchronous/Async_await)
- [Reactにおけるエラーバウンダリの使用](https://reactjs.org/docs/error-boundaries.html)
- [Express.jsのエラー処理](https://expressjs.com/en/guide/error-handling.html)
